# go defer语句

defer一般用于资源的释放和异常的捕捉，defer后的语句会在程序进行最后的return后再执行。

在 defer 归属的函数即将返回时，将延迟处理的语句按 defer 的逆序进行执行，也就是说，先被 defer 的语句最后被执行，最后被 defer 的语句，最先被执行。

```go
func CopyFile(dstName, srcName string) (written int64, err error){
	src, err := os.Open(srcName)
	if err != nil{
		return
	}
    dst, err := os.Creat(dstName)
    if err != nil{
        return
    }
    dst.Close()
    src.Close()
    return
}
```

以上代码中，如果后一个资源在打开后出现异常，那么前面所有打开的资源都没有办法关闭，所以最好在后面的异常处理中，对前面的资源进行释放。

但是如果所有的异常处理中都需要加上这个重复的释放资源代码，会很繁琐。

这个时候就用到了defer关键字。可以在每个占用的资源后面接上释放资源的代码并使用defer，这样最终都会将这些资源释放掉。

```go
src, err := os.Open(srcName)
defer src.Close()
if err != nil{
    return
}
```

# 异常的捕捉

go 并没有 try...catch模块，那是怎么进行异常捕捉和处理的呢？

go会出现panic异常，当出现这个异常后程序就会暂停了。

```go
func executePanic(){
	defer fmt.Println("defer func")
	panic("This is Panic Situation")
	fmt.Println("The function executes Completely")
}
func main(){
	executePanic()
	fmt.Println("Main block is executed completely...")
}
```

上述代码中，使用了手动执行panic函数来触发异常。当异常出现后，函数还是会调用defer中的函数，然后异常退出。上述代码输出如下：

```go
defer func
panic: This is Panic Situation 
程序的错误信息
```

但是如果defer后加上recover函数，程序就能正常运行，main函数能正常运行后退出。

```go
func executePanic(){
	defer func(){
		if errMsg := recover();errMsg != nil{
			fmt.Println(errMsg)
		}
	}()
	panic("This is Panic Situation")
	fmt.Println("The function executes Completely")
}
func main(){
	executePanic()
	fmt.Println("Main block is executed completely...")
}
```

此时我们在executePanic中用recover，那么挂掉的只是executePanic，他不会抛到main中，所以main能继续运行，继而main开辟的其他函数也能继续运行。

